<?xml version="1.0"?>
<robot xmlns:xacro="http://www.ros.org/wiki/xacro">
  <xacro:include filename="$(find manos_description)/urdf/grippers/schunk_pg70.transmission.xacro" />
  <xacro:include filename="$(find manos_description)/urdf/grippers/schunk_pg70.gazebo.xacro" />
  <xacro:macro name="schunk_pg70" params="parent name *origin ">
  <xacro:property name="pi" value="3.14159265" />
    <joint name="${name}_base_joint" type="fixed" >
      <parent link="${parent}" />
      <child link="${name}_base_link" />
      <xacro:insert_block name="origin" />
    </joint>

    <xacro:schunk_pg70_transmission name="${name}"/>
    <xacro:schunk_pg70_gazebo name="${name}" />

    <material name="silver">
      <color rgba="0.5 0.5 0.5 1"/>
    </material>

    <material name="light_silver">
      <color rgba="0.7 0.7 0.7 1"/>
    </material>

    <material name="white">
      <color rgba="1 1 1 1"/>
    </material>

    <material name="black">
      <color rgba="0 0 0 1"/>
    </material>

<!--     PALM -->
    
    <link name="${name}_base_link">
      <visual>
        <geometry>
          <mesh filename="package://manos_description/meshes/schunk_pg70/pg70.dae" />
        </geometry>
      </visual>
      <collision>
        <geometry>
          <mesh filename="package://manos_description/meshes/schunk_pg70/pg70.dae" />
        </geometry>
      </collision>
      <inertial>
          <origin xyz="0.000019 -0.000347 0.028892"/>
         <mass value="2.0"/>
         <inertia ixx="0.000002" ixy="0.0" ixz="0.0" iyy="0.000001" iyz="0.0" izz="0.000002"/>
      </inertial>
    </link>

<!-- LEFT FINGER BASE -->
    
    <joint name="${name}_finger1_joint" type="prismatic" >
      <parent link="${name}_base_link" />
      <child link="${name}_finger1_link" />
      <limit effort="100" lower="0.0015" upper="0.04" velocity="2.0"/>
      <origin xyz="0 0.0015 0.095" rpy="0 0 0"/>
      <axis xyz="0 1 0" />
    </joint>

    <link name="${name}_finger1_link">
      <visual>
        <geometry>
          <box size="0.03 0.01 0.01"/>
        </geometry>
        <material name="black"/>
      </visual>
      <collision>
        <geometry>
          <box size="0.03 0.01 0.01"/>
        </geometry>
      </collision>
      <inertial>
          <origin xyz="0.0 0.0 0.0"/>
         <mass value="0.2"/>
         <inertia ixx="1.0" ixy="0.0" ixz="0.0" iyy="1.0" iyz="0.0" izz="1.0"/>
      </inertial>
    </link>
    
<!-- LEFT FINGERTIP -->
    
    <joint name="${name}_fingertip_left_joint" type="fixed" >
      <parent link="${name}_finger1_link" />
      <child link="${name}_fingertip_left_link" />
      <origin xyz="0.015 -0.001 0.045" rpy="${pi/2} 0 -${pi/2}"/>
    </joint>

    <link name="${name}_fingertip_left_link">
      <visual>
         <geometry>
          <mesh filename="package://manos_description/meshes/schunk_pg70/finger.stl" />
        </geometry>
        <material name="white"/>
      </visual>
      <collision>
         <geometry>
          <mesh filename="package://manos_description/meshes/schunk_pg70/finger.stl" />
        </geometry>
      </collision>
    </link>
    
<!-- RIGHT FINGER BASE -->

    <joint name="${name}_finger2_joint" type="prismatic" >
      <!-- <mimic joint="${name}_finger1_joint" multiplier="1" offset="0"/> -->
      <parent link="${name}_base_link" />
      <child link="${name}_finger2_link" />
      <limit effort="100" lower="0.0015" upper="0.04" velocity="2.0"/>
      <origin xyz="0 -0.0015 0.095" rpy="-0 0 0"/>
      <axis xyz="0 -1 0" />
    </joint>

    <link name="${name}_finger2_link">
      <visual>
        <geometry>
          <box size="0.03 0.01 0.01"/>
        </geometry>
      <material name="black"/>
      </visual>
      <collision>
        <geometry>
          <box size="0.03 0.01 0.01"/>
        </geometry>
      </collision>
      <inertial>
          <origin xyz="0.0 0.0 0.0"/>
         <mass value="0.2"/>
         <inertia ixx="1.0" ixy="0.0" ixz="0.0" iyy="1.0" iyz="0.0" izz="1.0"/>
      </inertial>
    </link>
    
<!-- RIGHT FINGERTIP -->

    <joint name="${name}_fingertip_right_joint" type="fixed" >
      <parent link="${name}_finger2_link" />
      <child link="${name}_fingertip_right_link" />
     <origin xyz="-0.015 0.001 0.045" rpy="${pi/2} 0 ${pi/2}"/>
   </joint>

    <link name="${name}_fingertip_right_link">
      <visual>
         <geometry>
          <mesh filename="package://manos_description/meshes/schunk_pg70/finger.stl" />
        </geometry>
      <material name="white" />
      </visual>
      <collision>
         <geometry>
          <mesh filename="package://manos_description/meshes/schunk_pg70/finger.stl" />
        </geometry>
     </collision>
    </link>

         <link name="gripper_power_cable">
    <visual>
      <geometry>
        <cylinder length="0.035" radius="0.012"/>
      </geometry>
      <material name="light_silver"/>
    </visual>
    <collision>
      <geometry>
        <cylinder length="0.035" radius="0.012"/>
      </geometry>
    </collision>
 </link>

  <link name="gripper_power_box">
    <visual>
      <geometry>
        <box size="0.047 0.072 0.072"/>
      </geometry>
      <material name="silver"/>
    </visual>
    <collision>
      <geometry>
       <box size="0.047 0.072 0.072"/>
      </geometry>
    </collision>
  </link>

  <joint name="gripper_power_joint" type="fixed">
    <parent link="${name}_base_link"/>
    <child link="gripper_power_box"/>
    <origin xyz="0.0 -0.08 0.03" rpy="0.0 0.0 ${pi/2}" />
 </joint>

 <joint name="gripper_power_cable_joint" type="fixed">
    <parent link="gripper_power_box"/>
    <child link="gripper_power_cable"/>
    <origin xyz="-0.01 -0.042 -0.011" rpy="${pi/2} 0.0 0.0" />
 </joint>

  </xacro:macro>
</robot>
